[2018-04-13 14:56:11 +0000] [39101] [INFO] Starting gunicorn 19.7.1
[2018-04-13 14:56:11 +0000] [39101] [ERROR] Connection in use: ('0.0.0.0', 8000)
[2018-04-13 14:56:11 +0000] [39101] [ERROR] Retrying in 1 second.
[2018-04-13 14:56:12 +0000] [39101] [ERROR] Connection in use: ('0.0.0.0', 8000)
[2018-04-13 14:56:12 +0000] [39101] [ERROR] Retrying in 1 second.
[2018-04-13 14:56:13 +0000] [39101] [ERROR] Connection in use: ('0.0.0.0', 8000)
[2018-04-13 14:56:13 +0000] [39101] [ERROR] Retrying in 1 second.
[2018-04-13 14:56:14 +0000] [39101] [ERROR] Connection in use: ('0.0.0.0', 8000)
[2018-04-13 14:56:14 +0000] [39101] [ERROR] Retrying in 1 second.
[2018-04-13 14:56:15 +0000] [39101] [ERROR] Connection in use: ('0.0.0.0', 8000)
[2018-04-13 14:56:15 +0000] [39101] [ERROR] Retrying in 1 second.
[2018-04-13 14:56:16 +0000] [39101] [ERROR] Can't connect to ('0.0.0.0', 8000)
[2018-04-13 15:34:16 +0000] [49998] [INFO] Starting gunicorn 19.7.1
[2018-04-13 15:34:16 +0000] [49998] [INFO] Listening at: http://0.0.0.0:8000 (49998)
[2018-04-13 15:34:16 +0000] [49998] [INFO] Using worker: sync
[2018-04-13 15:34:16 +0000] [50011] [INFO] Booting worker with pid: 50011
[2018-04-13 15:34:16 +0000] [50011] [ERROR] Exception in worker process
Traceback (most recent call last):
  File "/usr/local/lib/python2.7/dist-packages/gunicorn/arbiter.py", line 578, in spawn_worker
    worker.init_process()
  File "/usr/local/lib/python2.7/dist-packages/gunicorn/workers/base.py", line 126, in init_process
    self.load_wsgi()
  File "/usr/local/lib/python2.7/dist-packages/gunicorn/workers/base.py", line 135, in load_wsgi
    self.wsgi = self.app.wsgi()
  File "/usr/local/lib/python2.7/dist-packages/gunicorn/app/base.py", line 67, in wsgi
    self.callable = self.load()
  File "/usr/local/lib/python2.7/dist-packages/gunicorn/app/wsgiapp.py", line 65, in load
    return self.load_wsgiapp()
  File "/usr/local/lib/python2.7/dist-packages/gunicorn/app/wsgiapp.py", line 52, in load_wsgiapp
    return util.import_app(self.app_uri)
  File "/usr/local/lib/python2.7/dist-packages/gunicorn/util.py", line 352, in import_app
    __import__(module)
  File "/home/atguigu/workspace/bookstore/bookstore/__init__.py", line 7, in <module>
    from .celery import app as celery_app
  File "/home/atguigu/workspace/bookstore/bookstore/celery.py", line 3, in <module>
    from celery import Celery
ImportError: No module named celery
[2018-04-13 15:34:16 +0000] [50011] [INFO] Worker exiting (pid: 50011)
[2018-04-13 15:34:16 +0000] [49998] [INFO] Shutting down: Master
[2018-04-13 15:34:16 +0000] [49998] [INFO] Reason: Worker failed to boot.
